[2022-05-15 01:31:46,250] {taskinstance.py:1035} INFO - Dependencies all met for <TaskInstance: dbt_dag.dbt_run scheduled__2022-05-14T01:31:44.285736+00:00 [queued]>
[2022-05-15 01:31:46,272] {taskinstance.py:1035} INFO - Dependencies all met for <TaskInstance: dbt_dag.dbt_run scheduled__2022-05-14T01:31:44.285736+00:00 [queued]>
[2022-05-15 01:31:46,273] {taskinstance.py:1241} INFO - 
--------------------------------------------------------------------------------
[2022-05-15 01:31:46,274] {taskinstance.py:1242} INFO - Starting attempt 1 of 1
[2022-05-15 01:31:46,275] {taskinstance.py:1243} INFO - 
--------------------------------------------------------------------------------
[2022-05-15 01:31:46,293] {taskinstance.py:1262} INFO - Executing <Task(BashOperator): dbt_run> on 2022-05-14 01:31:44.285736+00:00
[2022-05-15 01:31:46,299] {standard_task_runner.py:52} INFO - Started process 2672 to run task
[2022-05-15 01:31:46,316] {standard_task_runner.py:76} INFO - Running: ['***', 'tasks', 'run', 'dbt_dag', 'dbt_run', 'scheduled__2022-05-14T01:31:44.285736+00:00', '--job-id', '61', '--raw', '--subdir', 'DAGS_FOLDER/dbt_dag.py', '--cfg-path', '/tmp/tmp16zbl9qc', '--error-file', '/tmp/tmpb0qsqe_h']
[2022-05-15 01:31:46,318] {standard_task_runner.py:77} INFO - Job 61: Subtask dbt_run
[2022-05-15 01:31:46,399] {logging_mixin.py:109} INFO - Running <TaskInstance: dbt_dag.dbt_run scheduled__2022-05-14T01:31:44.285736+00:00 [running]> on host b0833397c3cf
[2022-05-15 01:31:46,458] {taskinstance.py:1429} INFO - Exporting the following env vars:
AIRFLOW_CTX_DAG_OWNER=***
AIRFLOW_CTX_DAG_ID=dbt_dag
AIRFLOW_CTX_TASK_ID=dbt_run
AIRFLOW_CTX_EXECUTION_DATE=2022-05-14T01:31:44.285736+00:00
AIRFLOW_CTX_DAG_RUN_ID=scheduled__2022-05-14T01:31:44.285736+00:00
[2022-05-15 01:31:46,460] {subprocess.py:62} INFO - Tmp dir root location: 
 /tmp
[2022-05-15 01:31:46,462] {subprocess.py:74} INFO - Running command: ['bash', '-c', '\n        cd dags/jaffle_shop\n        dbt run --profiles-dir .\n        ']
[2022-05-15 01:31:46,475] {subprocess.py:85} INFO - Output:
[2022-05-15 01:31:46,478] {subprocess.py:89} INFO - bash: line 1: cd: dags/jaffle_shop: No such file or directory
[2022-05-15 01:31:50,733] {subprocess.py:89} INFO - 01:31:50  Encountered an error:
[2022-05-15 01:31:50,734] {subprocess.py:89} INFO - Runtime Error
[2022-05-15 01:31:50,735] {subprocess.py:89} INFO -   fatal: Not a dbt project (or any of the parent directories). Missing dbt_project.yml file
[2022-05-15 01:31:50,858] {subprocess.py:93} INFO - Command exited with return code 2
[2022-05-15 01:31:50,889] {taskinstance.py:1703} ERROR - Task failed with exception
Traceback (most recent call last):
  File "/home/airflow/.local/lib/python3.7/site-packages/airflow/models/taskinstance.py", line 1332, in _run_raw_task
    self._execute_task_with_callbacks(context)
  File "/home/airflow/.local/lib/python3.7/site-packages/airflow/models/taskinstance.py", line 1458, in _execute_task_with_callbacks
    result = self._execute_task(context, self.task)
  File "/home/airflow/.local/lib/python3.7/site-packages/airflow/models/taskinstance.py", line 1514, in _execute_task
    result = execute_callable(context=context)
  File "/home/airflow/.local/lib/python3.7/site-packages/airflow/operators/bash.py", line 188, in execute
    f'Bash command failed. The command returned a non-zero exit code {result.exit_code}.'
airflow.exceptions.AirflowException: Bash command failed. The command returned a non-zero exit code 2.
[2022-05-15 01:31:50,926] {taskinstance.py:1280} INFO - Marking task as FAILED. dag_id=dbt_dag, task_id=dbt_run, execution_date=20220514T013144, start_date=20220515T013146, end_date=20220515T013150
[2022-05-15 01:31:50,948] {standard_task_runner.py:91} ERROR - Failed to execute job 61 for task dbt_run
Traceback (most recent call last):
  File "/home/airflow/.local/lib/python3.7/site-packages/airflow/task/task_runner/standard_task_runner.py", line 85, in _start_by_fork
    args.func(args, dag=self.dag)
  File "/home/airflow/.local/lib/python3.7/site-packages/airflow/cli/cli_parser.py", line 48, in command
    return func(*args, **kwargs)
  File "/home/airflow/.local/lib/python3.7/site-packages/airflow/utils/cli.py", line 92, in wrapper
    return f(*args, **kwargs)
  File "/home/airflow/.local/lib/python3.7/site-packages/airflow/cli/commands/task_command.py", line 292, in task_run
    _run_task_by_selected_method(args, dag, ti)
  File "/home/airflow/.local/lib/python3.7/site-packages/airflow/cli/commands/task_command.py", line 107, in _run_task_by_selected_method
    _run_raw_task(args, ti)
  File "/home/airflow/.local/lib/python3.7/site-packages/airflow/cli/commands/task_command.py", line 184, in _run_raw_task
    error_file=args.error_file,
  File "/home/airflow/.local/lib/python3.7/site-packages/airflow/utils/session.py", line 70, in wrapper
    return func(*args, session=session, **kwargs)
  File "/home/airflow/.local/lib/python3.7/site-packages/airflow/models/taskinstance.py", line 1332, in _run_raw_task
    self._execute_task_with_callbacks(context)
  File "/home/airflow/.local/lib/python3.7/site-packages/airflow/models/taskinstance.py", line 1458, in _execute_task_with_callbacks
    result = self._execute_task(context, self.task)
  File "/home/airflow/.local/lib/python3.7/site-packages/airflow/models/taskinstance.py", line 1514, in _execute_task
    result = execute_callable(context=context)
  File "/home/airflow/.local/lib/python3.7/site-packages/airflow/operators/bash.py", line 188, in execute
    f'Bash command failed. The command returned a non-zero exit code {result.exit_code}.'
airflow.exceptions.AirflowException: Bash command failed. The command returned a non-zero exit code 2.
[2022-05-15 01:31:51,008] {local_task_job.py:154} INFO - Task exited with return code 1
[2022-05-15 01:31:51,053] {local_task_job.py:264} INFO - 0 downstream tasks scheduled from follow-on schedule check
