[2022-05-17 01:30:59,447] {taskinstance.py:1035} INFO - Dependencies all met for <TaskInstance: model_level_dbt_dag.dbt_run.model.jaffle_shop.fct_customer_orders scheduled__2022-05-15T16:00:47.250021+00:00 [queued]>
[2022-05-17 01:30:59,463] {taskinstance.py:1035} INFO - Dependencies all met for <TaskInstance: model_level_dbt_dag.dbt_run.model.jaffle_shop.fct_customer_orders scheduled__2022-05-15T16:00:47.250021+00:00 [queued]>
[2022-05-17 01:30:59,464] {taskinstance.py:1241} INFO - 
--------------------------------------------------------------------------------
[2022-05-17 01:30:59,465] {taskinstance.py:1242} INFO - Starting attempt 5 of 8
[2022-05-17 01:30:59,466] {taskinstance.py:1243} INFO - 
--------------------------------------------------------------------------------
[2022-05-17 01:30:59,482] {taskinstance.py:1262} INFO - Executing <Task(BashOperator): dbt_run.model.jaffle_shop.fct_customer_orders> on 2022-05-15 16:00:47.250021+00:00
[2022-05-17 01:30:59,487] {standard_task_runner.py:52} INFO - Started process 116 to run task
[2022-05-17 01:30:59,498] {standard_task_runner.py:76} INFO - Running: ['***', 'tasks', 'run', 'model_level_dbt_dag', 'dbt_run.model.jaffle_shop.fct_customer_orders', 'scheduled__2022-05-15T16:00:47.250021+00:00', '--job-id', '535', '--raw', '--subdir', 'DAGS_FOLDER/model_level_dbt_dag.py', '--cfg-path', '/tmp/tmpwcdqumtl', '--error-file', '/tmp/tmpd69ez4r3']
[2022-05-17 01:30:59,500] {standard_task_runner.py:77} INFO - Job 535: Subtask dbt_run.model.jaffle_shop.fct_customer_orders
[2022-05-17 01:30:59,558] {logging_mixin.py:109} INFO - Running <TaskInstance: model_level_dbt_dag.dbt_run.model.jaffle_shop.fct_customer_orders scheduled__2022-05-15T16:00:47.250021+00:00 [running]> on host 9d5de636d688
[2022-05-17 01:30:59,618] {taskinstance.py:1429} INFO - Exporting the following env vars:
AIRFLOW_CTX_DAG_OWNER=luciano.naveiro
AIRFLOW_CTX_DAG_ID=model_level_dbt_dag
AIRFLOW_CTX_TASK_ID=dbt_run.model.jaffle_shop.fct_customer_orders
AIRFLOW_CTX_EXECUTION_DATE=2022-05-15T16:00:47.250021+00:00
AIRFLOW_CTX_DAG_RUN_ID=scheduled__2022-05-15T16:00:47.250021+00:00
[2022-05-17 01:30:59,620] {subprocess.py:62} INFO - Tmp dir root location: 
 /tmp
[2022-05-17 01:30:59,622] {subprocess.py:74} INFO - Running command: ['bash', '-c', 'dbt --no-write-json run --target dev --models fct_customer_orders --profiles-dir /opt/dbt/jaffle_shop --project-dir /opt/dbt/jaffle_shop']
[2022-05-17 01:30:59,634] {subprocess.py:85} INFO - Output:
[2022-05-17 01:31:03,438] {subprocess.py:89} INFO - 01:31:03  Running with dbt=1.1.0
[2022-05-17 01:31:03,600] {subprocess.py:89} INFO - 01:31:03  Found 5 models, 13 tests, 0 snapshots, 0 analyses, 170 macros, 0 operations, 0 seed files, 3 sources, 0 exposures, 0 metrics
[2022-05-17 01:31:03,610] {subprocess.py:89} INFO - 01:31:03
[2022-05-17 01:31:03,841] {subprocess.py:89} INFO - 01:31:03  Concurrency: 1 threads (target='dev')
[2022-05-17 01:31:03,843] {subprocess.py:89} INFO - 01:31:03
[2022-05-17 01:31:03,854] {subprocess.py:89} INFO - 01:31:03  1 of 1 START table model dev.fct_customer_orders ............................... [RUN]
[2022-05-17 01:31:03,944] {subprocess.py:89} INFO - 01:31:03  1 of 1 ERROR creating table model dev.fct_customer_orders ...................... [[31mERROR[0m in 0.09s]
[2022-05-17 01:31:03,973] {subprocess.py:89} INFO - 01:31:03
[2022-05-17 01:31:03,975] {subprocess.py:89} INFO - 01:31:03  Finished running 1 table model in 0.36s.
[2022-05-17 01:31:03,981] {subprocess.py:89} INFO - 01:31:03
[2022-05-17 01:31:03,983] {subprocess.py:89} INFO - 01:31:03  [31mCompleted with 1 error and 0 warnings:[0m
[2022-05-17 01:31:03,984] {subprocess.py:89} INFO - 01:31:03
[2022-05-17 01:31:03,986] {subprocess.py:89} INFO - 01:31:03  [33mDatabase Error in model fct_customer_orders (models/marts/core/fct_customer_orders.sql)[0m
[2022-05-17 01:31:03,987] {subprocess.py:89} INFO - 01:31:03    relation "dev.stg_jaffle_shop__customers" does not exist
[2022-05-17 01:31:03,989] {subprocess.py:89} INFO - 01:31:03    LINE 10:   select * from "raw"."dev"."stg_jaffle_shop__customers"
[2022-05-17 01:31:03,991] {subprocess.py:89} INFO - 01:31:03                             ^
[2022-05-17 01:31:03,993] {subprocess.py:89} INFO - 01:31:03    compiled SQL at target/run/jaffle_shop/models/marts/core/fct_customer_orders.sql
[2022-05-17 01:31:03,994] {subprocess.py:89} INFO - 01:31:03
[2022-05-17 01:31:03,996] {subprocess.py:89} INFO - 01:31:03  Done. PASS=0 WARN=0 ERROR=1 SKIP=0 TOTAL=1
[2022-05-17 01:31:05,208] {subprocess.py:93} INFO - Command exited with return code 1
[2022-05-17 01:31:05,238] {taskinstance.py:1703} ERROR - Task failed with exception
Traceback (most recent call last):
  File "/home/airflow/.local/lib/python3.7/site-packages/airflow/models/taskinstance.py", line 1332, in _run_raw_task
    self._execute_task_with_callbacks(context)
  File "/home/airflow/.local/lib/python3.7/site-packages/airflow/models/taskinstance.py", line 1458, in _execute_task_with_callbacks
    result = self._execute_task(context, self.task)
  File "/home/airflow/.local/lib/python3.7/site-packages/airflow/models/taskinstance.py", line 1514, in _execute_task
    result = execute_callable(context=context)
  File "/home/airflow/.local/lib/python3.7/site-packages/airflow/operators/bash.py", line 188, in execute
    f'Bash command failed. The command returned a non-zero exit code {result.exit_code}.'
airflow.exceptions.AirflowException: Bash command failed. The command returned a non-zero exit code 1.
[2022-05-17 01:31:05,255] {taskinstance.py:1280} INFO - Marking task as UP_FOR_RETRY. dag_id=model_level_dbt_dag, task_id=dbt_run.model.jaffle_shop.fct_customer_orders, execution_date=20220515T160047, start_date=20220517T013059, end_date=20220517T013105
[2022-05-17 01:31:05,283] {standard_task_runner.py:91} ERROR - Failed to execute job 535 for task dbt_run.model.jaffle_shop.fct_customer_orders
Traceback (most recent call last):
  File "/home/airflow/.local/lib/python3.7/site-packages/airflow/task/task_runner/standard_task_runner.py", line 85, in _start_by_fork
    args.func(args, dag=self.dag)
  File "/home/airflow/.local/lib/python3.7/site-packages/airflow/cli/cli_parser.py", line 48, in command
    return func(*args, **kwargs)
  File "/home/airflow/.local/lib/python3.7/site-packages/airflow/utils/cli.py", line 92, in wrapper
    return f(*args, **kwargs)
  File "/home/airflow/.local/lib/python3.7/site-packages/airflow/cli/commands/task_command.py", line 292, in task_run
    _run_task_by_selected_method(args, dag, ti)
  File "/home/airflow/.local/lib/python3.7/site-packages/airflow/cli/commands/task_command.py", line 107, in _run_task_by_selected_method
    _run_raw_task(args, ti)
  File "/home/airflow/.local/lib/python3.7/site-packages/airflow/cli/commands/task_command.py", line 184, in _run_raw_task
    error_file=args.error_file,
  File "/home/airflow/.local/lib/python3.7/site-packages/airflow/utils/session.py", line 70, in wrapper
    return func(*args, session=session, **kwargs)
  File "/home/airflow/.local/lib/python3.7/site-packages/airflow/models/taskinstance.py", line 1332, in _run_raw_task
    self._execute_task_with_callbacks(context)
  File "/home/airflow/.local/lib/python3.7/site-packages/airflow/models/taskinstance.py", line 1458, in _execute_task_with_callbacks
    result = self._execute_task(context, self.task)
  File "/home/airflow/.local/lib/python3.7/site-packages/airflow/models/taskinstance.py", line 1514, in _execute_task
    result = execute_callable(context=context)
  File "/home/airflow/.local/lib/python3.7/site-packages/airflow/operators/bash.py", line 188, in execute
    f'Bash command failed. The command returned a non-zero exit code {result.exit_code}.'
airflow.exceptions.AirflowException: Bash command failed. The command returned a non-zero exit code 1.
[2022-05-17 01:31:05,329] {local_task_job.py:154} INFO - Task exited with return code 1
[2022-05-17 01:31:05,395] {local_task_job.py:264} INFO - 0 downstream tasks scheduled from follow-on schedule check
