[2022-06-04 03:30:16,219] {taskinstance.py:1035} INFO - Dependencies all met for <TaskInstance: model_level_dbt_dag.dbt_test.test.jaffle_shop.assert_positive_total_for_payments_daily scheduled__2022-06-03T02:53:52.617168+00:00 [queued]>
[2022-06-04 03:30:16,279] {taskinstance.py:1035} INFO - Dependencies all met for <TaskInstance: model_level_dbt_dag.dbt_test.test.jaffle_shop.assert_positive_total_for_payments_daily scheduled__2022-06-03T02:53:52.617168+00:00 [queued]>
[2022-06-04 03:30:16,281] {taskinstance.py:1241} INFO - 
--------------------------------------------------------------------------------
[2022-06-04 03:30:16,282] {taskinstance.py:1242} INFO - Starting attempt 1 of 4
[2022-06-04 03:30:16,284] {taskinstance.py:1243} INFO - 
--------------------------------------------------------------------------------
[2022-06-04 03:30:16,338] {taskinstance.py:1262} INFO - Executing <Task(BashOperator): dbt_test.test.jaffle_shop.assert_positive_total_for_payments_daily> on 2022-06-03 02:53:52.617168+00:00
[2022-06-04 03:30:16,377] {standard_task_runner.py:52} INFO - Started process 2885 to run task
[2022-06-04 03:30:16,440] {standard_task_runner.py:76} INFO - Running: ['***', 'tasks', 'run', 'model_level_dbt_dag', 'dbt_test.test.jaffle_shop.assert_positive_total_for_payments_daily', 'scheduled__2022-06-03T02:53:52.617168+00:00', '--job-id', '250', '--raw', '--subdir', 'DAGS_FOLDER/model_level_dbt_dag.py', '--cfg-path', '/tmp/tmpvty3pi_p', '--error-file', '/tmp/tmp26nh7ijk']
[2022-06-04 03:30:16,461] {standard_task_runner.py:77} INFO - Job 250: Subtask dbt_test.test.jaffle_shop.assert_positive_total_for_payments_daily
[2022-06-04 03:30:16,826] {logging_mixin.py:109} INFO - Running <TaskInstance: model_level_dbt_dag.dbt_test.test.jaffle_shop.assert_positive_total_for_payments_daily scheduled__2022-06-03T02:53:52.617168+00:00 [running]> on host 3d17a0db806e
[2022-06-04 03:30:17,028] {taskinstance.py:1429} INFO - Exporting the following env vars:
AIRFLOW_CTX_DAG_OWNER=luciano.naveiro
AIRFLOW_CTX_DAG_ID=model_level_dbt_dag
AIRFLOW_CTX_TASK_ID=dbt_test.test.jaffle_shop.assert_positive_total_for_payments_daily
AIRFLOW_CTX_EXECUTION_DATE=2022-06-03T02:53:52.617168+00:00
AIRFLOW_CTX_DAG_RUN_ID=scheduled__2022-06-03T02:53:52.617168+00:00
[2022-06-04 03:30:17,031] {subprocess.py:62} INFO - Tmp dir root location: 
 /tmp
[2022-06-04 03:30:17,037] {subprocess.py:74} INFO - Running command: ['bash', '-c', 'dbt --no-write-json test --target dev --select assert_positive_total_for_payments_daily --profiles-dir /opt/dbt/jaffle_shop --project-dir /opt/dbt/jaffle_shop']
[2022-06-04 03:30:17,075] {subprocess.py:85} INFO - Output:
[2022-06-04 03:30:47,329] {subprocess.py:89} INFO - 03:30:47  Running with dbt=1.1.0
[2022-06-04 03:30:47,561] {subprocess.py:89} INFO - 03:30:47  Unable to do partial parsing because config vars, config profile, or config target have changed
[2022-06-04 03:31:02,189] {subprocess.py:89} INFO - 03:31:02  Found 5 models, 14 tests, 0 snapshots, 0 analyses, 170 macros, 0 operations, 0 seed files, 3 sources, 0 exposures, 0 metrics
[2022-06-04 03:31:02,240] {subprocess.py:89} INFO - 03:31:02
[2022-06-04 03:31:03,385] {subprocess.py:89} INFO - 03:31:03  Concurrency: 1 threads (target='dev')
[2022-06-04 03:31:03,403] {subprocess.py:89} INFO - 03:31:03
[2022-06-04 03:31:03,682] {subprocess.py:89} INFO - 03:31:03  1 of 1 START test assert_positive_total_for_payments_daily ..................... [RUN]
[2022-06-04 03:31:03,875] {subprocess.py:89} INFO - 03:31:03  1 of 1 ERROR assert_positive_total_for_payments_daily .......................... [[31mERROR[0m in 0.19s]
[2022-06-04 03:31:04,276] {subprocess.py:89} INFO - 03:31:04
[2022-06-04 03:31:04,310] {subprocess.py:89} INFO - 03:31:04  Finished running 1 test in 1.95s.
[2022-06-04 03:31:04,422] {subprocess.py:89} INFO - 03:31:04
[2022-06-04 03:31:04,490] {subprocess.py:89} INFO - 03:31:04  [31mCompleted with 1 error and 0 warnings:[0m
[2022-06-04 03:31:04,535] {subprocess.py:89} INFO - 03:31:04
[2022-06-04 03:31:04,596] {subprocess.py:89} INFO - 03:31:04  [33mCompilation Error in test assert_positive_total_for_payments_daily (tests/assert_positive_total_for_payments_daily.sql)[0m
[2022-06-04 03:31:04,646] {subprocess.py:89} INFO - 03:31:04    Required var 'date' not found in config:
[2022-06-04 03:31:04,777] {subprocess.py:89} INFO - 03:31:04    Vars supplied to assert_positive_total_for_payments_daily = {}
[2022-06-04 03:31:05,051] {subprocess.py:89} INFO - 03:31:05
[2022-06-04 03:31:05,179] {subprocess.py:89} INFO - 03:31:05    > in test assert_positive_total_for_payments_daily (tests/assert_positive_total_for_payments_daily.sql)
[2022-06-04 03:31:05,213] {subprocess.py:89} INFO - 03:31:05    > called by test assert_positive_total_for_payments_daily (tests/assert_positive_total_for_payments_daily.sql)
[2022-06-04 03:31:05,355] {subprocess.py:89} INFO - 03:31:05
[2022-06-04 03:31:05,390] {subprocess.py:89} INFO - 03:31:05  Done. PASS=0 WARN=0 ERROR=1 SKIP=0 TOTAL=1
[2022-06-04 03:31:08,381] {subprocess.py:93} INFO - Command exited with return code 1
[2022-06-04 03:31:08,525] {taskinstance.py:1703} ERROR - Task failed with exception
Traceback (most recent call last):
  File "/home/airflow/.local/lib/python3.7/site-packages/airflow/models/taskinstance.py", line 1332, in _run_raw_task
    self._execute_task_with_callbacks(context)
  File "/home/airflow/.local/lib/python3.7/site-packages/airflow/models/taskinstance.py", line 1458, in _execute_task_with_callbacks
    result = self._execute_task(context, self.task)
  File "/home/airflow/.local/lib/python3.7/site-packages/airflow/models/taskinstance.py", line 1514, in _execute_task
    result = execute_callable(context=context)
  File "/home/airflow/.local/lib/python3.7/site-packages/airflow/operators/bash.py", line 188, in execute
    f'Bash command failed. The command returned a non-zero exit code {result.exit_code}.'
airflow.exceptions.AirflowException: Bash command failed. The command returned a non-zero exit code 1.
[2022-06-04 03:31:08,672] {taskinstance.py:1280} INFO - Marking task as UP_FOR_RETRY. dag_id=model_level_dbt_dag, task_id=dbt_test.test.jaffle_shop.assert_positive_total_for_payments_daily, execution_date=20220603T025352, start_date=20220604T033016, end_date=20220604T033108
[2022-06-04 03:31:08,823] {standard_task_runner.py:91} ERROR - Failed to execute job 250 for task dbt_test.test.jaffle_shop.assert_positive_total_for_payments_daily
Traceback (most recent call last):
  File "/home/airflow/.local/lib/python3.7/site-packages/airflow/task/task_runner/standard_task_runner.py", line 85, in _start_by_fork
    args.func(args, dag=self.dag)
  File "/home/airflow/.local/lib/python3.7/site-packages/airflow/cli/cli_parser.py", line 48, in command
    return func(*args, **kwargs)
  File "/home/airflow/.local/lib/python3.7/site-packages/airflow/utils/cli.py", line 92, in wrapper
    return f(*args, **kwargs)
  File "/home/airflow/.local/lib/python3.7/site-packages/airflow/cli/commands/task_command.py", line 292, in task_run
    _run_task_by_selected_method(args, dag, ti)
  File "/home/airflow/.local/lib/python3.7/site-packages/airflow/cli/commands/task_command.py", line 107, in _run_task_by_selected_method
    _run_raw_task(args, ti)
  File "/home/airflow/.local/lib/python3.7/site-packages/airflow/cli/commands/task_command.py", line 184, in _run_raw_task
    error_file=args.error_file,
  File "/home/airflow/.local/lib/python3.7/site-packages/airflow/utils/session.py", line 70, in wrapper
    return func(*args, session=session, **kwargs)
  File "/home/airflow/.local/lib/python3.7/site-packages/airflow/models/taskinstance.py", line 1332, in _run_raw_task
    self._execute_task_with_callbacks(context)
  File "/home/airflow/.local/lib/python3.7/site-packages/airflow/models/taskinstance.py", line 1458, in _execute_task_with_callbacks
    result = self._execute_task(context, self.task)
  File "/home/airflow/.local/lib/python3.7/site-packages/airflow/models/taskinstance.py", line 1514, in _execute_task
    result = execute_callable(context=context)
  File "/home/airflow/.local/lib/python3.7/site-packages/airflow/operators/bash.py", line 188, in execute
    f'Bash command failed. The command returned a non-zero exit code {result.exit_code}.'
airflow.exceptions.AirflowException: Bash command failed. The command returned a non-zero exit code 1.
[2022-06-04 03:31:09,037] {local_task_job.py:154} INFO - Task exited with return code 1
[2022-06-04 03:31:09,297] {local_task_job.py:264} INFO - 0 downstream tasks scheduled from follow-on schedule check
