[2022-05-15 04:23:48,473] {taskinstance.py:1035} INFO - Dependencies all met for <TaskInstance: simple_dag.dbt_test scheduled__2022-05-14T03:38:59.887034+00:00 [queued]>
[2022-05-15 04:23:48,488] {taskinstance.py:1035} INFO - Dependencies all met for <TaskInstance: simple_dag.dbt_test scheduled__2022-05-14T03:38:59.887034+00:00 [queued]>
[2022-05-15 04:23:48,489] {taskinstance.py:1241} INFO - 
--------------------------------------------------------------------------------
[2022-05-15 04:23:48,490] {taskinstance.py:1242} INFO - Starting attempt 3 of 3
[2022-05-15 04:23:48,491] {taskinstance.py:1243} INFO - 
--------------------------------------------------------------------------------
[2022-05-15 04:23:48,508] {taskinstance.py:1262} INFO - Executing <Task(BashOperator): dbt_test> on 2022-05-14 03:38:59.887034+00:00
[2022-05-15 04:23:48,517] {standard_task_runner.py:52} INFO - Started process 6424 to run task
[2022-05-15 04:23:48,523] {standard_task_runner.py:76} INFO - Running: ['***', 'tasks', 'run', 'simple_dag', 'dbt_test', 'scheduled__2022-05-14T03:38:59.887034+00:00', '--job-id', '113', '--raw', '--subdir', 'DAGS_FOLDER/simple_dbt_dag.py', '--cfg-path', '/tmp/tmp4_23_owu', '--error-file', '/tmp/tmp16mymlua']
[2022-05-15 04:23:48,525] {standard_task_runner.py:77} INFO - Job 113: Subtask dbt_test
[2022-05-15 04:23:48,584] {logging_mixin.py:109} INFO - Running <TaskInstance: simple_dag.dbt_test scheduled__2022-05-14T03:38:59.887034+00:00 [running]> on host b0833397c3cf
[2022-05-15 04:23:48,644] {taskinstance.py:1429} INFO - Exporting the following env vars:
AIRFLOW_CTX_DAG_OWNER=***
AIRFLOW_CTX_DAG_ID=simple_dag
AIRFLOW_CTX_TASK_ID=dbt_test
AIRFLOW_CTX_EXECUTION_DATE=2022-05-14T03:38:59.887034+00:00
AIRFLOW_CTX_DAG_RUN_ID=scheduled__2022-05-14T03:38:59.887034+00:00
[2022-05-15 04:23:48,646] {subprocess.py:62} INFO - Tmp dir root location: 
 /tmp
[2022-05-15 04:23:48,649] {subprocess.py:74} INFO - Running command: ['bash', '-c', '\n        cd /opt/***/dags/jaffle_shop\n        dbt test --profiles-dir .\n        ']
[2022-05-15 04:23:48,662] {subprocess.py:85} INFO - Output:
[2022-05-15 04:23:52,088] {subprocess.py:89} INFO - 04:23:52  Running with dbt=1.1.0
[2022-05-15 04:23:52,326] {subprocess.py:89} INFO - 04:23:52  [[33mWARNING[0m]: Test 'test.jaffle_shop.relationships_stg_jaffle_shop__orders_customer_id__customer_id__ref_stg_customers_.a37476cdbb' (models/staging/jaffle_shop/stg_jaffle_shop.yml) depends on a node named 'stg_customers' which was not found
[2022-05-15 04:23:52,362] {subprocess.py:89} INFO - 04:23:52  Found 5 models, 11 tests, 0 snapshots, 0 analyses, 170 macros, 0 operations, 0 seed files, 3 sources, 0 exposures, 0 metrics
[2022-05-15 04:23:52,369] {subprocess.py:89} INFO - 04:23:52
[2022-05-15 04:23:52,487] {subprocess.py:89} INFO - 04:23:52  Concurrency: 1 threads (target='dev')
[2022-05-15 04:23:52,489] {subprocess.py:89} INFO - 04:23:52
[2022-05-15 04:23:52,503] {subprocess.py:89} INFO - 04:23:52  1 of 11 START test accepted_values_stg_jaffle_shop__orders_status__completed__shipped__returned__return_pending__placed  [RUN]
[2022-05-15 04:23:52,591] {subprocess.py:89} INFO - 04:23:52  1 of 11 ERROR accepted_values_stg_jaffle_shop__orders_status__completed__shipped__returned__return_pending__placed  [[31mERROR[0m in 0.08s]
[2022-05-15 04:23:52,604] {subprocess.py:89} INFO - 04:23:52  2 of 11 START test not_null_stg_jaffle_shop__customers_customer_id ............. [RUN]
[2022-05-15 04:23:52,657] {subprocess.py:89} INFO - 04:23:52  2 of 11 PASS not_null_stg_jaffle_shop__customers_customer_id ................... [[32mPASS[0m in 0.05s]
[2022-05-15 04:23:52,662] {subprocess.py:89} INFO - 04:23:52  3 of 11 START test not_null_stg_jaffle_shop__orders_order_id ................... [RUN]
[2022-05-15 04:23:52,718] {subprocess.py:89} INFO - 04:23:52  3 of 11 PASS not_null_stg_jaffle_shop__orders_order_id ......................... [[32mPASS[0m in 0.05s]
[2022-05-15 04:23:52,724] {subprocess.py:89} INFO - 04:23:52  4 of 11 START test source_not_null_jaffle_shop_customers_id .................... [RUN]
[2022-05-15 04:23:52,789] {subprocess.py:89} INFO - 04:23:52  4 of 11 PASS source_not_null_jaffle_shop_customers_id .......................... [[32mPASS[0m in 0.06s]
[2022-05-15 04:23:52,795] {subprocess.py:89} INFO - 04:23:52  5 of 11 START test source_not_null_jaffle_shop_orders_id ....................... [RUN]
[2022-05-15 04:23:52,849] {subprocess.py:89} INFO - 04:23:52  5 of 11 PASS source_not_null_jaffle_shop_orders_id ............................. [[32mPASS[0m in 0.05s]
[2022-05-15 04:23:52,856] {subprocess.py:89} INFO - 04:23:52  6 of 11 START test source_not_null_stripe_payment_id ........................... [RUN]
[2022-05-15 04:23:52,924] {subprocess.py:89} INFO - 04:23:52  6 of 11 PASS source_not_null_stripe_payment_id ................................. [[32mPASS[0m in 0.07s]
[2022-05-15 04:23:52,931] {subprocess.py:89} INFO - 04:23:52  7 of 11 START test source_unique_jaffle_shop_customers_id ...................... [RUN]
[2022-05-15 04:23:52,994] {subprocess.py:89} INFO - 04:23:52  7 of 11 PASS source_unique_jaffle_shop_customers_id ............................ [[32mPASS[0m in 0.06s]
[2022-05-15 04:23:52,999] {subprocess.py:89} INFO - 04:23:52  8 of 11 START test source_unique_jaffle_shop_orders_id ......................... [RUN]
[2022-05-15 04:23:53,062] {subprocess.py:89} INFO - 04:23:53  8 of 11 PASS source_unique_jaffle_shop_orders_id ............................... [[32mPASS[0m in 0.06s]
[2022-05-15 04:23:53,069] {subprocess.py:89} INFO - 04:23:53  9 of 11 START test source_unique_stripe_payment_id ............................. [RUN]
[2022-05-15 04:23:53,131] {subprocess.py:89} INFO - 04:23:53  9 of 11 PASS source_unique_stripe_payment_id ................................... [[32mPASS[0m in 0.06s]
[2022-05-15 04:23:53,137] {subprocess.py:89} INFO - 04:23:53  10 of 11 START test unique_stg_jaffle_shop__customers_customer_id .............. [RUN]
[2022-05-15 04:23:53,225] {subprocess.py:89} INFO - 04:23:53  10 of 11 PASS unique_stg_jaffle_shop__customers_customer_id .................... [[32mPASS[0m in 0.09s]
[2022-05-15 04:23:53,231] {subprocess.py:89} INFO - 04:23:53  11 of 11 START test unique_stg_jaffle_shop__orders_order_id .................... [RUN]
[2022-05-15 04:23:53,303] {subprocess.py:89} INFO - 04:23:53  11 of 11 PASS unique_stg_jaffle_shop__orders_order_id .......................... [[32mPASS[0m in 0.07s]
[2022-05-15 04:23:53,453] {subprocess.py:89} INFO - 04:23:53
[2022-05-15 04:23:53,456] {subprocess.py:89} INFO - 04:23:53  Finished running 11 tests in 1.08s.
[2022-05-15 04:23:53,493] {subprocess.py:89} INFO - 04:23:53
[2022-05-15 04:23:53,499] {subprocess.py:89} INFO - 04:23:53  [31mCompleted with 1 error and 0 warnings:[0m
[2022-05-15 04:23:53,502] {subprocess.py:89} INFO - 04:23:53
[2022-05-15 04:23:53,506] {subprocess.py:89} INFO - 04:23:53  [33mDatabase Error in test accepted_values_stg_jaffle_shop__orders_status__completed__shipped__returned__return_pending__placed (models/staging/jaffle_shop/stg_jaffle_shop.yml)[0m
[2022-05-15 04:23:53,510] {subprocess.py:89} INFO - 04:23:53    column "status" does not exist
[2022-05-15 04:23:53,516] {subprocess.py:89} INFO - 04:23:53    LINE 14:         status as value_field,
[2022-05-15 04:23:53,520] {subprocess.py:89} INFO - 04:23:53                     ^
[2022-05-15 04:23:53,525] {subprocess.py:89} INFO - 04:23:53    compiled SQL at target/run/jaffle_shop/models/staging/jaffle_shop/stg_jaffle_shop.yml/accepted_values_stg_jaffle_sho_3ad15fa7d7f8de69cc0666c8351b51a7.sql
[2022-05-15 04:23:53,530] {subprocess.py:89} INFO - 04:23:53
[2022-05-15 04:23:53,533] {subprocess.py:89} INFO - 04:23:53  Done. PASS=10 WARN=0 ERROR=1 SKIP=0 TOTAL=11
[2022-05-15 04:23:55,078] {subprocess.py:93} INFO - Command exited with return code 1
[2022-05-15 04:23:55,096] {taskinstance.py:1703} ERROR - Task failed with exception
Traceback (most recent call last):
  File "/home/airflow/.local/lib/python3.7/site-packages/airflow/models/taskinstance.py", line 1332, in _run_raw_task
    self._execute_task_with_callbacks(context)
  File "/home/airflow/.local/lib/python3.7/site-packages/airflow/models/taskinstance.py", line 1458, in _execute_task_with_callbacks
    result = self._execute_task(context, self.task)
  File "/home/airflow/.local/lib/python3.7/site-packages/airflow/models/taskinstance.py", line 1514, in _execute_task
    result = execute_callable(context=context)
  File "/home/airflow/.local/lib/python3.7/site-packages/airflow/operators/bash.py", line 188, in execute
    f'Bash command failed. The command returned a non-zero exit code {result.exit_code}.'
airflow.exceptions.AirflowException: Bash command failed. The command returned a non-zero exit code 1.
[2022-05-15 04:23:55,126] {taskinstance.py:1280} INFO - Marking task as FAILED. dag_id=simple_dag, task_id=dbt_test, execution_date=20220514T033859, start_date=20220515T042348, end_date=20220515T042355
[2022-05-15 04:23:55,147] {standard_task_runner.py:91} ERROR - Failed to execute job 113 for task dbt_test
Traceback (most recent call last):
  File "/home/airflow/.local/lib/python3.7/site-packages/airflow/task/task_runner/standard_task_runner.py", line 85, in _start_by_fork
    args.func(args, dag=self.dag)
  File "/home/airflow/.local/lib/python3.7/site-packages/airflow/cli/cli_parser.py", line 48, in command
    return func(*args, **kwargs)
  File "/home/airflow/.local/lib/python3.7/site-packages/airflow/utils/cli.py", line 92, in wrapper
    return f(*args, **kwargs)
  File "/home/airflow/.local/lib/python3.7/site-packages/airflow/cli/commands/task_command.py", line 292, in task_run
    _run_task_by_selected_method(args, dag, ti)
  File "/home/airflow/.local/lib/python3.7/site-packages/airflow/cli/commands/task_command.py", line 107, in _run_task_by_selected_method
    _run_raw_task(args, ti)
  File "/home/airflow/.local/lib/python3.7/site-packages/airflow/cli/commands/task_command.py", line 184, in _run_raw_task
    error_file=args.error_file,
  File "/home/airflow/.local/lib/python3.7/site-packages/airflow/utils/session.py", line 70, in wrapper
    return func(*args, session=session, **kwargs)
  File "/home/airflow/.local/lib/python3.7/site-packages/airflow/models/taskinstance.py", line 1332, in _run_raw_task
    self._execute_task_with_callbacks(context)
  File "/home/airflow/.local/lib/python3.7/site-packages/airflow/models/taskinstance.py", line 1458, in _execute_task_with_callbacks
    result = self._execute_task(context, self.task)
  File "/home/airflow/.local/lib/python3.7/site-packages/airflow/models/taskinstance.py", line 1514, in _execute_task
    result = execute_callable(context=context)
  File "/home/airflow/.local/lib/python3.7/site-packages/airflow/operators/bash.py", line 188, in execute
    f'Bash command failed. The command returned a non-zero exit code {result.exit_code}.'
airflow.exceptions.AirflowException: Bash command failed. The command returned a non-zero exit code 1.
[2022-05-15 04:23:55,192] {local_task_job.py:154} INFO - Task exited with return code 1
[2022-05-15 04:23:55,226] {local_task_job.py:264} INFO - 0 downstream tasks scheduled from follow-on schedule check
