[2022-05-19 15:46:11,719] {taskinstance.py:1035} INFO - Dependencies all met for <TaskInstance: model_level_dbt_dag.dbt_validate.dbt_debug scheduled__2022-05-18T15:43:01.271269+00:00 [queued]>
[2022-05-19 15:46:11,732] {taskinstance.py:1035} INFO - Dependencies all met for <TaskInstance: model_level_dbt_dag.dbt_validate.dbt_debug scheduled__2022-05-18T15:43:01.271269+00:00 [queued]>
[2022-05-19 15:46:11,733] {taskinstance.py:1241} INFO - 
--------------------------------------------------------------------------------
[2022-05-19 15:46:11,734] {taskinstance.py:1242} INFO - Starting attempt 2 of 4
[2022-05-19 15:46:11,735] {taskinstance.py:1243} INFO - 
--------------------------------------------------------------------------------
[2022-05-19 15:46:11,752] {taskinstance.py:1262} INFO - Executing <Task(BashOperator): dbt_validate.dbt_debug> on 2022-05-18 15:43:01.271269+00:00
[2022-05-19 15:46:11,770] {standard_task_runner.py:52} INFO - Started process 82 to run task
[2022-05-19 15:46:11,777] {standard_task_runner.py:76} INFO - Running: ['***', 'tasks', 'run', 'model_level_dbt_dag', 'dbt_validate.dbt_debug', 'scheduled__2022-05-18T15:43:01.271269+00:00', '--job-id', '38', '--raw', '--subdir', 'DAGS_FOLDER/model_level_dbt_dag.py', '--cfg-path', '/tmp/tmprbhz1a6h', '--error-file', '/tmp/tmppmc465nz']
[2022-05-19 15:46:11,788] {standard_task_runner.py:77} INFO - Job 38: Subtask dbt_validate.dbt_debug
[2022-05-19 15:46:11,909] {logging_mixin.py:109} INFO - Running <TaskInstance: model_level_dbt_dag.dbt_validate.dbt_debug scheduled__2022-05-18T15:43:01.271269+00:00 [running]> on host 2b634a1d286c
[2022-05-19 15:46:11,994] {taskinstance.py:1429} INFO - Exporting the following env vars:
AIRFLOW_CTX_DAG_OWNER=luciano.naveiro
AIRFLOW_CTX_DAG_ID=model_level_dbt_dag
AIRFLOW_CTX_TASK_ID=dbt_validate.dbt_debug
AIRFLOW_CTX_EXECUTION_DATE=2022-05-18T15:43:01.271269+00:00
AIRFLOW_CTX_DAG_RUN_ID=scheduled__2022-05-18T15:43:01.271269+00:00
[2022-05-19 15:46:11,997] {subprocess.py:62} INFO - Tmp dir root location: 
 /tmp
[2022-05-19 15:46:11,999] {subprocess.py:74} INFO - Running command: ['bash', '-c', '\n        dbt debug --profiles-dir /opt/dbt/jaffle_shop --project-dir /opt/dbt/jaffle_shop\n        ']
[2022-05-19 15:46:12,023] {subprocess.py:85} INFO - Output:
[2022-05-19 15:46:12,030] {subprocess.py:89} INFO - bash: line 1: dbt: command not found
[2022-05-19 15:46:12,034] {subprocess.py:93} INFO - Command exited with return code 127
[2022-05-19 15:46:12,069] {taskinstance.py:1703} ERROR - Task failed with exception
Traceback (most recent call last):
  File "/home/airflow/.local/lib/python3.7/site-packages/airflow/models/taskinstance.py", line 1332, in _run_raw_task
    self._execute_task_with_callbacks(context)
  File "/home/airflow/.local/lib/python3.7/site-packages/airflow/models/taskinstance.py", line 1458, in _execute_task_with_callbacks
    result = self._execute_task(context, self.task)
  File "/home/airflow/.local/lib/python3.7/site-packages/airflow/models/taskinstance.py", line 1514, in _execute_task
    result = execute_callable(context=context)
  File "/home/airflow/.local/lib/python3.7/site-packages/airflow/operators/bash.py", line 188, in execute
    f'Bash command failed. The command returned a non-zero exit code {result.exit_code}.'
airflow.exceptions.AirflowException: Bash command failed. The command returned a non-zero exit code 127.
[2022-05-19 15:46:12,082] {taskinstance.py:1280} INFO - Marking task as UP_FOR_RETRY. dag_id=model_level_dbt_dag, task_id=dbt_validate.dbt_debug, execution_date=20220518T154301, start_date=20220519T154611, end_date=20220519T154612
[2022-05-19 15:46:12,121] {standard_task_runner.py:91} ERROR - Failed to execute job 38 for task dbt_validate.dbt_debug
Traceback (most recent call last):
  File "/home/airflow/.local/lib/python3.7/site-packages/airflow/task/task_runner/standard_task_runner.py", line 85, in _start_by_fork
    args.func(args, dag=self.dag)
  File "/home/airflow/.local/lib/python3.7/site-packages/airflow/cli/cli_parser.py", line 48, in command
    return func(*args, **kwargs)
  File "/home/airflow/.local/lib/python3.7/site-packages/airflow/utils/cli.py", line 92, in wrapper
    return f(*args, **kwargs)
  File "/home/airflow/.local/lib/python3.7/site-packages/airflow/cli/commands/task_command.py", line 292, in task_run
    _run_task_by_selected_method(args, dag, ti)
  File "/home/airflow/.local/lib/python3.7/site-packages/airflow/cli/commands/task_command.py", line 107, in _run_task_by_selected_method
    _run_raw_task(args, ti)
  File "/home/airflow/.local/lib/python3.7/site-packages/airflow/cli/commands/task_command.py", line 184, in _run_raw_task
    error_file=args.error_file,
  File "/home/airflow/.local/lib/python3.7/site-packages/airflow/utils/session.py", line 70, in wrapper
    return func(*args, session=session, **kwargs)
  File "/home/airflow/.local/lib/python3.7/site-packages/airflow/models/taskinstance.py", line 1332, in _run_raw_task
    self._execute_task_with_callbacks(context)
  File "/home/airflow/.local/lib/python3.7/site-packages/airflow/models/taskinstance.py", line 1458, in _execute_task_with_callbacks
    result = self._execute_task(context, self.task)
  File "/home/airflow/.local/lib/python3.7/site-packages/airflow/models/taskinstance.py", line 1514, in _execute_task
    result = execute_callable(context=context)
  File "/home/airflow/.local/lib/python3.7/site-packages/airflow/operators/bash.py", line 188, in execute
    f'Bash command failed. The command returned a non-zero exit code {result.exit_code}.'
airflow.exceptions.AirflowException: Bash command failed. The command returned a non-zero exit code 127.
[2022-05-19 15:46:12,186] {local_task_job.py:154} INFO - Task exited with return code 1
[2022-05-19 15:46:12,270] {local_task_job.py:264} INFO - 0 downstream tasks scheduled from follow-on schedule check
