[2022-05-15 15:24:28,345] {taskinstance.py:1035} INFO - Dependencies all met for <TaskInstance: models_dbt_dag.dbt_test.test.jaffle_shop.assert_positive_total_for_payments scheduled__2022-05-14T15:15:58.068711+00:00 [queued]>
[2022-05-15 15:24:28,459] {taskinstance.py:1035} INFO - Dependencies all met for <TaskInstance: models_dbt_dag.dbt_test.test.jaffle_shop.assert_positive_total_for_payments scheduled__2022-05-14T15:15:58.068711+00:00 [queued]>
[2022-05-15 15:24:28,467] {taskinstance.py:1241} INFO - 
--------------------------------------------------------------------------------
[2022-05-15 15:24:28,472] {taskinstance.py:1242} INFO - Starting attempt 2 of 2
[2022-05-15 15:24:28,477] {taskinstance.py:1243} INFO - 
--------------------------------------------------------------------------------
[2022-05-15 15:24:28,565] {taskinstance.py:1262} INFO - Executing <Task(BashOperator): dbt_test.test.jaffle_shop.assert_positive_total_for_payments> on 2022-05-14 15:15:58.068711+00:00
[2022-05-15 15:24:28,611] {standard_task_runner.py:76} INFO - Running: ['***', 'tasks', 'run', 'models_dbt_dag', 'dbt_test.test.jaffle_shop.assert_positive_total_for_payments', 'scheduled__2022-05-14T15:15:58.068711+00:00', '--job-id', '167', '--raw', '--subdir', 'DAGS_FOLDER/models_dbt_dag.py', '--cfg-path', '/tmp/tmpa0khm01a', '--error-file', '/tmp/tmpy_a627tq']
[2022-05-15 15:24:28,613] {standard_task_runner.py:77} INFO - Job 167: Subtask dbt_test.test.jaffle_shop.assert_positive_total_for_payments
[2022-05-15 15:24:28,603] {standard_task_runner.py:52} INFO - Started process 9859 to run task
[2022-05-15 15:24:28,726] {logging_mixin.py:109} INFO - Running <TaskInstance: models_dbt_dag.dbt_test.test.jaffle_shop.assert_positive_total_for_payments scheduled__2022-05-14T15:15:58.068711+00:00 [running]> on host b0833397c3cf
[2022-05-15 15:24:28,845] {taskinstance.py:1429} INFO - Exporting the following env vars:
AIRFLOW_CTX_DAG_OWNER=***
AIRFLOW_CTX_DAG_ID=models_dbt_dag
AIRFLOW_CTX_TASK_ID=dbt_test.test.jaffle_shop.assert_positive_total_for_payments
AIRFLOW_CTX_EXECUTION_DATE=2022-05-14T15:15:58.068711+00:00
AIRFLOW_CTX_DAG_RUN_ID=scheduled__2022-05-14T15:15:58.068711+00:00
[2022-05-15 15:24:28,848] {subprocess.py:62} INFO - Tmp dir root location: 
 /tmp
[2022-05-15 15:24:28,850] {subprocess.py:74} INFO - Running command: ['bash', '-c', 'dbt --no-write-json test --target dev --select assert_positive_total_for_payments --profiles-dir /opt/***/dags/jaffle_shop --project-dir /opt/***/dags/jaffle_shop']
[2022-05-15 15:24:28,893] {subprocess.py:85} INFO - Output:
[2022-05-15 15:24:47,591] {subprocess.py:89} INFO - 15:24:47  Running with dbt=1.1.0
[2022-05-15 15:24:48,456] {subprocess.py:89} INFO - 15:24:48  Found 5 models, 13 tests, 0 snapshots, 0 analyses, 170 macros, 0 operations, 0 seed files, 3 sources, 0 exposures, 0 metrics
[2022-05-15 15:24:48,490] {subprocess.py:89} INFO - 15:24:48
[2022-05-15 15:24:49,169] {subprocess.py:89} INFO - 15:24:49  Concurrency: 1 threads (target='dev')
[2022-05-15 15:24:49,180] {subprocess.py:89} INFO - 15:24:49
[2022-05-15 15:24:49,320] {subprocess.py:89} INFO - 15:24:49  1 of 1 START test assert_positive_total_for_payments ........................... [RUN]
[2022-05-15 15:24:49,986] {subprocess.py:89} INFO - 15:24:49  1 of 1 ERROR assert_positive_total_for_payments ................................ [[31mERROR[0m in 0.64s]
[2022-05-15 15:24:50,171] {subprocess.py:89} INFO - 15:24:50
[2022-05-15 15:24:50,172] {subprocess.py:89} INFO - 15:24:50  Finished running 1 test in 1.66s.
[2022-05-15 15:24:50,183] {subprocess.py:89} INFO - 15:24:50
[2022-05-15 15:24:50,197] {subprocess.py:89} INFO - 15:24:50  [31mCompleted with 1 error and 0 warnings:[0m
[2022-05-15 15:24:50,205] {subprocess.py:89} INFO - 15:24:50
[2022-05-15 15:24:50,207] {subprocess.py:89} INFO - 15:24:50  [33mDatabase Error in test assert_positive_total_for_payments (tests/assert_positive_total_for_payments.sql)[0m
[2022-05-15 15:24:50,214] {subprocess.py:89} INFO - 15:24:50    column "amount" does not exist
[2022-05-15 15:24:50,226] {subprocess.py:89} INFO - 15:24:50    LINE 16:         sum(amount) AS total_amount
[2022-05-15 15:24:50,250] {subprocess.py:89} INFO - 15:24:50                         ^
[2022-05-15 15:24:50,274] {subprocess.py:89} INFO - 15:24:50    compiled SQL at target/run/jaffle_shop/tests/assert_positive_total_for_payments.sql
[2022-05-15 15:24:50,282] {subprocess.py:89} INFO - 15:24:50
[2022-05-15 15:24:50,284] {subprocess.py:89} INFO - 15:24:50  Done. PASS=0 WARN=0 ERROR=1 SKIP=0 TOTAL=1
[2022-05-15 15:24:54,030] {subprocess.py:93} INFO - Command exited with return code 1
[2022-05-15 15:24:54,188] {taskinstance.py:1703} ERROR - Task failed with exception
Traceback (most recent call last):
  File "/home/airflow/.local/lib/python3.7/site-packages/airflow/models/taskinstance.py", line 1332, in _run_raw_task
    self._execute_task_with_callbacks(context)
  File "/home/airflow/.local/lib/python3.7/site-packages/airflow/models/taskinstance.py", line 1458, in _execute_task_with_callbacks
    result = self._execute_task(context, self.task)
  File "/home/airflow/.local/lib/python3.7/site-packages/airflow/models/taskinstance.py", line 1514, in _execute_task
    result = execute_callable(context=context)
  File "/home/airflow/.local/lib/python3.7/site-packages/airflow/operators/bash.py", line 188, in execute
    f'Bash command failed. The command returned a non-zero exit code {result.exit_code}.'
airflow.exceptions.AirflowException: Bash command failed. The command returned a non-zero exit code 1.
[2022-05-15 15:24:54,748] {taskinstance.py:1280} INFO - Marking task as FAILED. dag_id=models_dbt_dag, task_id=dbt_test.test.jaffle_shop.assert_positive_total_for_payments, execution_date=20220514T151558, start_date=20220515T152428, end_date=20220515T152454
[2022-05-15 15:24:54,861] {standard_task_runner.py:91} ERROR - Failed to execute job 167 for task dbt_test.test.jaffle_shop.assert_positive_total_for_payments
Traceback (most recent call last):
  File "/home/airflow/.local/lib/python3.7/site-packages/airflow/task/task_runner/standard_task_runner.py", line 85, in _start_by_fork
    args.func(args, dag=self.dag)
  File "/home/airflow/.local/lib/python3.7/site-packages/airflow/cli/cli_parser.py", line 48, in command
    return func(*args, **kwargs)
  File "/home/airflow/.local/lib/python3.7/site-packages/airflow/utils/cli.py", line 92, in wrapper
    return f(*args, **kwargs)
  File "/home/airflow/.local/lib/python3.7/site-packages/airflow/cli/commands/task_command.py", line 292, in task_run
    _run_task_by_selected_method(args, dag, ti)
  File "/home/airflow/.local/lib/python3.7/site-packages/airflow/cli/commands/task_command.py", line 107, in _run_task_by_selected_method
    _run_raw_task(args, ti)
  File "/home/airflow/.local/lib/python3.7/site-packages/airflow/cli/commands/task_command.py", line 184, in _run_raw_task
    error_file=args.error_file,
  File "/home/airflow/.local/lib/python3.7/site-packages/airflow/utils/session.py", line 70, in wrapper
    return func(*args, session=session, **kwargs)
  File "/home/airflow/.local/lib/python3.7/site-packages/airflow/models/taskinstance.py", line 1332, in _run_raw_task
    self._execute_task_with_callbacks(context)
  File "/home/airflow/.local/lib/python3.7/site-packages/airflow/models/taskinstance.py", line 1458, in _execute_task_with_callbacks
    result = self._execute_task(context, self.task)
  File "/home/airflow/.local/lib/python3.7/site-packages/airflow/models/taskinstance.py", line 1514, in _execute_task
    result = execute_callable(context=context)
  File "/home/airflow/.local/lib/python3.7/site-packages/airflow/operators/bash.py", line 188, in execute
    f'Bash command failed. The command returned a non-zero exit code {result.exit_code}.'
airflow.exceptions.AirflowException: Bash command failed. The command returned a non-zero exit code 1.
[2022-05-15 15:24:55,052] {local_task_job.py:154} INFO - Task exited with return code 1
[2022-05-15 15:24:55,327] {local_task_job.py:264} INFO - 0 downstream tasks scheduled from follow-on schedule check
