[2022-05-15 01:35:34,440] {taskinstance.py:1035} INFO - Dependencies all met for <TaskInstance: dbt_dag.test scheduled__2022-05-14T01:33:26.251894+00:00 [queued]>
[2022-05-15 01:35:34,458] {taskinstance.py:1035} INFO - Dependencies all met for <TaskInstance: dbt_dag.test scheduled__2022-05-14T01:33:26.251894+00:00 [queued]>
[2022-05-15 01:35:34,459] {taskinstance.py:1241} INFO - 
--------------------------------------------------------------------------------
[2022-05-15 01:35:34,460] {taskinstance.py:1242} INFO - Starting attempt 2 of 2
[2022-05-15 01:35:34,461] {taskinstance.py:1243} INFO - 
--------------------------------------------------------------------------------
[2022-05-15 01:35:34,479] {taskinstance.py:1262} INFO - Executing <Task(BashOperator): test> on 2022-05-14 01:33:26.251894+00:00
[2022-05-15 01:35:34,485] {standard_task_runner.py:52} INFO - Started process 2867 to run task
[2022-05-15 01:35:34,490] {standard_task_runner.py:76} INFO - Running: ['***', 'tasks', 'run', 'dbt_dag', 'test', 'scheduled__2022-05-14T01:33:26.251894+00:00', '--job-id', '66', '--raw', '--subdir', 'DAGS_FOLDER/dbt_dag.py', '--cfg-path', '/tmp/tmpk3swvnon', '--error-file', '/tmp/tmpp0higca4']
[2022-05-15 01:35:34,492] {standard_task_runner.py:77} INFO - Job 66: Subtask test
[2022-05-15 01:35:34,552] {logging_mixin.py:109} INFO - Running <TaskInstance: dbt_dag.test scheduled__2022-05-14T01:33:26.251894+00:00 [running]> on host b0833397c3cf
[2022-05-15 01:35:34,607] {taskinstance.py:1429} INFO - Exporting the following env vars:
AIRFLOW_CTX_DAG_OWNER=***
AIRFLOW_CTX_DAG_ID=dbt_dag
AIRFLOW_CTX_TASK_ID=test
AIRFLOW_CTX_EXECUTION_DATE=2022-05-14T01:33:26.251894+00:00
AIRFLOW_CTX_DAG_RUN_ID=scheduled__2022-05-14T01:33:26.251894+00:00
[2022-05-15 01:35:34,609] {subprocess.py:62} INFO - Tmp dir root location: 
 /tmp
[2022-05-15 01:35:34,611] {subprocess.py:74} INFO - Running command: ['bash', '-c', '\n        ls /usr/local/***/\n        ']
[2022-05-15 01:35:34,623] {subprocess.py:85} INFO - Output:
[2022-05-15 01:35:34,631] {subprocess.py:89} INFO - ls: cannot access '/usr/local/***/': No such file or directory
[2022-05-15 01:35:34,632] {subprocess.py:93} INFO - Command exited with return code 2
[2022-05-15 01:35:34,648] {taskinstance.py:1703} ERROR - Task failed with exception
Traceback (most recent call last):
  File "/home/airflow/.local/lib/python3.7/site-packages/airflow/models/taskinstance.py", line 1332, in _run_raw_task
    self._execute_task_with_callbacks(context)
  File "/home/airflow/.local/lib/python3.7/site-packages/airflow/models/taskinstance.py", line 1458, in _execute_task_with_callbacks
    result = self._execute_task(context, self.task)
  File "/home/airflow/.local/lib/python3.7/site-packages/airflow/models/taskinstance.py", line 1514, in _execute_task
    result = execute_callable(context=context)
  File "/home/airflow/.local/lib/python3.7/site-packages/airflow/operators/bash.py", line 188, in execute
    f'Bash command failed. The command returned a non-zero exit code {result.exit_code}.'
airflow.exceptions.AirflowException: Bash command failed. The command returned a non-zero exit code 2.
[2022-05-15 01:35:34,657] {taskinstance.py:1280} INFO - Marking task as FAILED. dag_id=dbt_dag, task_id=test, execution_date=20220514T013326, start_date=20220515T013534, end_date=20220515T013534
[2022-05-15 01:35:34,673] {standard_task_runner.py:91} ERROR - Failed to execute job 66 for task test
Traceback (most recent call last):
  File "/home/airflow/.local/lib/python3.7/site-packages/airflow/task/task_runner/standard_task_runner.py", line 85, in _start_by_fork
    args.func(args, dag=self.dag)
  File "/home/airflow/.local/lib/python3.7/site-packages/airflow/cli/cli_parser.py", line 48, in command
    return func(*args, **kwargs)
  File "/home/airflow/.local/lib/python3.7/site-packages/airflow/utils/cli.py", line 92, in wrapper
    return f(*args, **kwargs)
  File "/home/airflow/.local/lib/python3.7/site-packages/airflow/cli/commands/task_command.py", line 292, in task_run
    _run_task_by_selected_method(args, dag, ti)
  File "/home/airflow/.local/lib/python3.7/site-packages/airflow/cli/commands/task_command.py", line 107, in _run_task_by_selected_method
    _run_raw_task(args, ti)
  File "/home/airflow/.local/lib/python3.7/site-packages/airflow/cli/commands/task_command.py", line 184, in _run_raw_task
    error_file=args.error_file,
  File "/home/airflow/.local/lib/python3.7/site-packages/airflow/utils/session.py", line 70, in wrapper
    return func(*args, session=session, **kwargs)
  File "/home/airflow/.local/lib/python3.7/site-packages/airflow/models/taskinstance.py", line 1332, in _run_raw_task
    self._execute_task_with_callbacks(context)
  File "/home/airflow/.local/lib/python3.7/site-packages/airflow/models/taskinstance.py", line 1458, in _execute_task_with_callbacks
    result = self._execute_task(context, self.task)
  File "/home/airflow/.local/lib/python3.7/site-packages/airflow/models/taskinstance.py", line 1514, in _execute_task
    result = execute_callable(context=context)
  File "/home/airflow/.local/lib/python3.7/site-packages/airflow/operators/bash.py", line 188, in execute
    f'Bash command failed. The command returned a non-zero exit code {result.exit_code}.'
airflow.exceptions.AirflowException: Bash command failed. The command returned a non-zero exit code 2.
[2022-05-15 01:35:34,706] {local_task_job.py:154} INFO - Task exited with return code 1
[2022-05-15 01:35:34,762] {local_task_job.py:264} INFO - 0 downstream tasks scheduled from follow-on schedule check
